Workbook
Name Slicer_Daibetes_status: #N/A
Name Slicer_weight_status: #N/A

Sheet Customer Names
A1: Customer ID | B1: name
A2: Id1 | B2: Hawks, Ms. Kelly
A3: Id2 | B3: Lehner, Mr. Matthew D
A4: Id3 | B4: Lu, Mr. Phil
A5: Id4 | B5: Osborne, Ms. Kelsey
A6: Id5 | B6: Kadala, Ms. Kristyn
A7: Id6 | B7: Baker, Mr. Russell B.
A8: Id7 | B8: Macpherson, Mr. Scott
A9: Id8 | B9: Hallman, Mr. Stephen
A10: Id9 | B10: Moran, Mr. Patrick R.
A11: Id10 | B11: Benner, Ms. Brooke N.
A12: Id11 | B12: Fierro Vargas, Ms. Paola Andrea
... A2336: Id2335 | B2336: German, Mr. Aaron K

Sheet Medical Examinations
A1: Customer ID | B1: BMI | C1: HBA1C | D1: Heart Issues | E1: Any Transplants | F1: Cancer history | G1: NumberOfMajorSurgeries | H1: smoker
A2: Id1 | B2: 47.41 | C2: 7.47 | D2: No | E2: No | F2: No | G2: No major surgery | H2: yes
A3: Id2 | B3: 30.36 | C3: 5.77 | D3: No | E3: No | F3: No | G3: No major surgery | H3: yes
A4: Id3 | B4: 34.485 | C4: 11.87 | D4: yes | E4: No | F4: No | G4: 2 | H4: yes
A5: Id4 | B5: 38.095 | C5: 6.05 | D5: No | E5: No | F5: No | G5: No major surgery | H5: yes
A6: Id5 | B6: 35.53 | C6: 5.45 | D6: No | E6: No | F6: No | G6: No major surgery | H6: yes
A7: Id6 | B7: 32.8 | C7: 6.59 | D7: No | E7: No | F7: No | G7: No major surgery | H7: yes
A8: Id7 | B8: 36.4 | C8: 6.07 | D8: No | E8: No | F8: No | G8: No major surgery | H8: yes
A9: Id8 | B9: 36.96 | C9: 7.93 | D9: No | E9: No | F9: No | G9: 3 | H9: yes
A10: Id9 | B10: 41.14 | C10: 9.58 | D10: yes | E10: No | F10: Yes | G10: 1 | H10: yes
A11: Id10 | B11: 38.06 | C11: 10.79 | D11: No | E11: No | F11: No | G11: No major surgery | H11: yes
A12: Id11 | B12: 37.7 | C12: 5.96 | D12: yes | E12: No | F12: No | G12: 2 | H12: yes
A13: Id12 | B13: 42.13 | C13: 11.9 | D13: No | E13: No | F13: No | G13: No major surgery | H13: yes
A14: Id13 | B14: 40.92 | C14: 8.41 | D14: No | E14: No | F14: No | G14: No major surgery | H14: yes
A15: Id14 | B15: 40.565 | C15: 7.02 | D15: No | E15: No | F15: No | G15: No major surgery | H15: yes
A16: Id15 | B16: 36.385 | C16: 7.59 | D16: yes | E16: No | F16: No | G16: 2 | H16: yes
A17: Id16 | B17: 39.9 | C17: 11.32 | D17: No | E17: No | F17: No | G17: No major surgery | H17: yes
A18: Id17 | B18: 33.8 | C18: 7.67 | D18: No | E18: No | F18: No | G18: 3 | H18: yes
A19: Id18 | B19: 36.765 | C19: 7.29 | D19: yes | E19: No | F19: Yes | G19: 1 | H19: yes
A20: Id19 | B20: 36.955 | C20: 4.72 | D20: yes | E20: No | F20: No | G20: 1 | H20: yes
A21: Id20 | B21: 42.9 | C21: 11.41 | D21: No | E21: No | F21: No | G21: No major surgery | H21: yes
A22: Id21 | B22: 36.3 | C22: 11.5 | D22: yes | E22: No | F22: No | G22: 2 | H22: yes
A23: Id22 | B23: 32.2 | C23: 6.22 | D23: yes | E23: No | F23: No | G23: 2 | H23: yes
A24: Id23 | B24: 31.3 | C24: 11.38 | D24: No | E24: No | F24: No | G24: 3 | H24: yes
A25: Id24 | B25: 41.8 | C25: 7.89 | D25: yes | E25: No | F25: No | G25: 2 | H25: yes
A26: Id25 | B26: 35.09 | C26: 4.38 | D26: yes | E26: No | F26: No | G26: 2 | H26: yes
A27: Id26 | B27: 33.88 | C27: 7.01 | D27: No | E27: No | F27: No | G27: 3 | H27: yes
A28: Id27 | B28: 30.875 | C28: 11.88 | D28: No | E28: No | F28: No | G28: No major surgery | H28: yes
A29: Id28 | B29: 36.86 | C29: 5.19 | D29: yes | E29: No | F29: Yes | G29: 1 | H29: yes
A30: Id29 | B30: 35.86 | C30: 6.74 | D30: yes | E30: No | F30: No | G30: 2 | H30: yes
A31: Id30 | B31: 37.05 | C31: 8.44 | D31: No | E31: No | F31: No | G31: No major surgery | H31: yes
A32: Id31 | B32: 43.89 | C32: 8.71 | D32: No | E32: No | F32: No | G32: No major surgery | H32: yes
A33: Id32 | B33: 42.35 | C33: 5.08 | D33: yes | E33: No | F33: No | G33: No major surgery | H33: yes
A34: Id33 | B34: 31.35 | C34: 6.86 | D34: No | E34: No | F34: No | G34: No major surgery | H34: yes
A35: Id34 | B35: 47.6 | C35: 5.95 | D35: yes | E35: No | F35: No | G35: No major surgery | H35: yes
A36: Id35 | B36: 46.2 | C36: 6.09 | D36: No | E36: No | F36: Yes | G36: 1 | H36: yes
A37: Id36 | B37: 32.015 | C37: 11.75 | D37: No | E37: No | F37: No | G37: No major surgery | H37: yes
A38: Id37 | B38: 40.565 | C38: 7.37 | D38: No | E38: No | F38: No | G38: No major surgery | H38: yes
A39: Id38 | B39: 32.45 | C39: 11.91 | D39: No | E39: No | F39: No | G39: No major surgery | H39: yes
A40: Id39 | B40: 34.96 | C40: 6.52 | D40: No | E40: No | F40: No | G40: No major surgery | H40: yes
...

Sheet Hospitalisation Details
A1: Customer ID | B1: year | C1: month | D1: date | E1: children | F1: charges | G1: Hospital tier | H1: City tier | I1: State ID
A2: Id2335 | B2: 1992 | C2: Jul | D2: 9 | E2: 0 | F2: 563.84 | G2: tier - 2 | H2: tier - 3 | I2: R1013
A3: Id2334 | B3: 1992 | C3: Nov | D3: 30 | E3: 0 | F3: 570.62 | G3: tier - 2 | H3: tier - 1 | I3: R1013
A4: Id2333 | B4: 1993 | C4: Jun | D4: 30 | E4: 0 | F4: 600 | G4: tier - 2 | H4: tier - 1 | I4: R1013
A5: Id2332 | B5: 1992 | C5: Sep | D5: 13 | E5: 0 | F5: 604.54 | G5: tier - 3 | H5: tier - 3 | I5: R1013
A6: Id2331 | B6: 1998 | C6: Jul | D6: 27 | E6: 0 | F6: 637.26 | G6: tier - 3 | H6: tier - 3 | I6: R1013
A7: Id2330 | B7: 2001 | C7: Nov | D7: 20 | E7: 0 | F7: 646.14 | G7: tier - 3 | H7: tier - 3 | I7: R1012
A8: Id2329 | B8: 1993 | C8: Jun | D8: 1 | E8: 0 | F8: 650 | G8: tier - 3 | H8: tier - 3 | I8: R1013
A9: Id2328 | B9: 1995 | C9: Jul | D9: 4 | E9: 0 | F9: 650 | G9: tier - 3 | H9: tier - 3 | I9: R1013
A10: Id2327 | B10: 2002 | C10: Nov | D10: 29 | E10: 0 | F10: 668 | G10: tier - 3 | H10: tier - 2 | I10: R1012
A11: Id2326 | B11: 1997 | C11: Nov | D11: 9 | E11: 0 | F11: 670 | G11: tier - 3 | H11: tier - 3 | I11: R1013
A12: Id2325 | B12: 2001 | C12: Sep | D12: 12 | E12: 0 | F12: 687.54 | G12: tier - 3 | H12: tier - 2 | I12: R1013
A13: Id2324 | B13: 1999 | C13: Dec | D13: 26 | E13: 0 | F13: 700 | G13: ? | H13: tier - 3 | I13: R1013
... A1050: Id1290 | B1050: 1977 | C1050: Jul | D1050: 26 | E1050: 2 | F1050: 8527.53 | G1050: tier - 2 | H1050: tier - 2 | I1050: R1013
A1051: Id1289 | B1051: ? | C1051: Jul | D1051: 24 | E1051: 0 | F1051: 8534.67 | G1051: tier - 2 | H1051: tier - 3 | I1051: R1024
A1052: Id1288 | B1052: 1981 | C1052: Dec | D1052: 27 | E1052: 3 | F1052: 8538.29 | G1052: tier - 2 | H1052: tier - 3 | I1052: R1024
A1053: Id1287 | B1053: 1975 | C1053: Nov | D1053: 6 | E1053: 1 | F1053: 8539.67 | G1053: tier - 2 | H1053: tier - 3 | I1053: R1011
A1054: Id1286 | B1054: ? | C1054: Dec | D1054: 12 | E1054: 1 | F1054: 8547.69 | G1054: tier - 2 | H1054: tier - 1 | I1054: R1013
A1055: Id1285 | B1055: 1975 | C1055: Aug | D1055: 6 | E1055: 1 | F1055: 8551.35 | G1055: tier - 2 | H1055: tier - 2 | I1055: R1011
A1056: Id1284 | B1056: 1975 | C1056: Aug | D1056: 21 | E1056: 1 | F1056: 8556.91 | G1056: tier - 2 | H1056: tier - 1 | I1056: R1011
A1057: Id1283 | B1057: 1988 | C1057: Sep | D1057: 21 | E1057: 3 | F1057: 8567.25 | G1057: tier - 2 | H1057: tier - 1 | I1057: R1012
A1058: Id1282 | B1058: 1975 | C1058: Sep | D1058: 26 | E1058: 1 | F1058: 8569.86 | G1058: tier - 2 | H1058: tier - 3 | I1058: R1013
A1059: Id1281 | B1059: 1982 | C1059: Dec | D1059: 6 | E1059: 3 | F1059: 8572.04 | G1059: tier - 2 | H1059: tier - 2 | I1059: R1021
A1060: Id1280 | B1060: 1987 | C1060: Nov | D1060: 11 | E1060: 3 | F1060: 8573.3 | G1060: tier - 2 | H1060: tier - 2 | I1060: R1021
A1061: Id1279 | B1061: 1983 | C1061: Dec | D1061: 30 | E1061: 5 | F1061: 8582.3 | G1061: tier - 2 | H1061: tier - 1 | I1061: R1013
A1062: Id1278 | B1062: 1983 | C1062: Jul | D1062: 25 | E1062: 5 | F1062: 8596.83 | G1062: tier - 2 | H1062: tier - 3 | I1062: R1013
A1063: Id1277 | B1063: 1973 | C1063: Jul | D1063: 11 | E1063: 0 | F1063: 8601.33 | G1063: tier - 2 | H1063: tier - 1 | I1063: R1013
A1064: Id1276 | B1064: 1977 | C1064: Sep | D1064: 24 | E1064: 2 | F1064: 8603.82 | G1064: tier - 2 | H1064: tier - 1 | I1064: R1019
A1065: Id1275 | B1065: 1977 | C1065: Nov | D1065: 12 | E1065: 2 | F1065: 8604.48 | G1065: tier - 3 | H1065: tier - 2 | I1065: R1016
A1066: Id1274 | B1066: 1977 | C1066: Oct | D1066: 15 | E1066: 3 | F1066: 8605.36 | G1066: tier - 2 | H1066: tier - 2 | I1066: R1013
... A2344: Id1 | B2344: 1968 | C2344: Oct | D2344: 12 | E2344: 0 | F2344: 63770.43 | G2344: tier - 1 | H2344: tier - 3 | I2344: R1013

Sheet data cleaning 
A2: ()Data Cleaning:
A4: 1) | B4: =COUNTIF('Medical Examinations'!A1:H2336,"?") -> 0 | C4: in Medical Examinations
B5: =COUNTIF('Hospitalisation Details'!A1:I2344,"?") -> 12 | C5: in Hospitalisation Details
A7: 2) | C7: year | D7: month | F7: 3) | G7: City tier | H7: Hospital tier | I7: smoker | K7: most occuring | N7: 4) | O7: State ID
C8: 1992 | D8: Jul | G8: tier - 3 | H8: tier - 2 | I8: yes | K8: city tier | L8: {=INDEX(G8:G2350,MODE(MATCH(G8:G2350,G8:G2350,0)))} -> tier - 2 | O8: R1013
C9: 1992 | D9: Nov | G9: tier - 1 | H9: tier - 2 | I9: yes | K9: hospital tier | L9: {=INDEX(H8:H2350,MODE(MATCH(H8:H2350,H8:H2350,0)))} -> tier - 2 | O9: R1013
C10: 1993 | D10: Jun | G10: tier - 1 | H10: tier - 2 | I10: yes | K10: smoker | L10: {=INDEX(I8:I2342,MODE(MATCH(I8:I2342,I8:I2342,0)))} -> No | O10: R1013
C11: 1992 | D11: Sep | G11: tier - 3 | H11: tier - 3 | I11: yes | O11: R1013
C12: 1998 | D12: Jul | G12: tier - 3 | H12: tier - 3 | I12: yes | O12: R1013
C13: 2001 | D13: Nov | G13: tier - 3 | H13: tier - 3 | I13: yes | O13: R1012
C14: 1993 | D14: Jun | G14: tier - 3 | H14: tier - 3 | I14: yes | O14: R1013
C15: 1995 | D15: Jul | G15: tier - 3 | H15: tier - 3 | I15: yes | O15: R1013
C16: 2002 | D16: Nov | G16: tier - 2 | H16: tier - 3 | I16: yes | O16: R1012
C17: 1997 | D17: Nov | G17: tier - 3 | H17: tier - 3 | I17: yes | O17: R1013
C18: 2001 | D18: Sep | G18: tier - 2 | H18: tier - 3 | I18: yes | O18: R1013
C19: 1999 | D19: Dec | G19: tier - 3 | H19: tier - 2 | I19: yes | O19: R1013
C20: 1999 | D20: Dec | G20: tier - 1 | H20: tier - 3 | I20: yes | O20: R1013
C21: 2002 | D21: =D18 -> Sep | G21: tier - 1 | H21: tier - 3 | I21: yes | O21: R1012
C22: 1993 | D22: Aug | G22: tier - 1 | H22: tier - 3 | I22: yes | O22: R1013
C23: 1996 | D23: Oct | G23: tier - 3 | H23: tier - 3 | I23: yes | O23: R1013
C24: 1993 | D24: Jun | G24: tier - 3 | H24: tier - 3 | I24: yes | O24: R1013
C25: 1996 | D25: =D18 -> Sep | G25: tier - 2 | H25: tier - 3 | I25: yes | O25: R1012
C26: 1995 | D26: Dec | G26: tier - 2 | H26: tier - 3 | I26: yes | O26: R1013
C27: 2004 | D27: Oct | G27: tier - 2 | H27: tier - 3 | I27: yes | O27: R1011
C28: 2000 | D28: Nov | G28: tier - 1 | H28: tier - 3 | I28: yes | O28: R1013
C29: 1993 | D29: Nov | G29: tier - 1 | H29: tier - 3 | I29: yes | O29: R1013
C30: 1994 | D30: Oct | G30: tier - 1 | H30: tier - 3 | I30: yes | O30: R1013
C31: 1995 | D31: Oct | G31: tier - 1 | H31: tier - 3 | I31: yes | O31: R1013
C32: 2001 | D32: Aug | G32: tier - 2 | H32: tier - 3 | I32: yes | O32: R1013
C33: 1994 | D33: Nov | G33: tier - 2 | H33: tier - 3 | I33: yes | O33: R1013
C34: 2000 | D34: Oct | G34: tier - 2 | H34: tier - 3 | I34: yes | O34: R1013
C35: 1999 | D35: Aug | G35: tier - 2 | H35: tier - 3 | I35: yes | O35: R1013
C36: 1995 | D36: Oct | G36: tier - 1 | H36: tier - 3 | I36: yes | O36: R1013
C37: 1994 | D37: Nov | G37: tier - 2 | H37: tier - 3 | I37: yes | O37: R1013
... C1056: 1977 | D1056: Jul | G1056: tier - 2 | H1056: tier - 2 | I1056: No | O1056: R1013
C1057: =AVERAGE('Hospitalisation Details'!B2:B2344) -> 1982.8415 | D1057: Jul | G1057: tier - 3 | H1057: tier - 2 | I1057: No | O1057: R1024
C1058: 1981 | D1058: Dec | G1058: tier - 3 | H1058: tier - 2 | I1058: No | O1058: R1024
C1059: 1975 | D1059: Nov | G1059: tier - 3 | H1059: tier - 2 | I1059: No | O1059: R1011
C1060: =AVERAGE('Hospitalisation Details'!B2:B2344) -> 1982.8415 | D1060: Dec | G1060: tier - 1 | H1060: tier - 2 | I1060: No | O1060: R1013
C1061: 1975 | D1061: Aug | G1061: tier - 2 | H1061: tier - 2 | I1061: No | O1061: R1011
...

Sheet data transformation 
A1: 2) data transformation
A4: 1) | B4: name | C4: first name | D4: title | E4: last name | G4: 2) | H4: NumberOfMajorSurgeries | J4: 3) | N4: 4) | O4: BMI | P4: weight status | R4: 5) | S4: HBA1C | T4: Daibetes status | W4: 6) | X4: year | Y4: month | Z4: date | AA4: date of birth | AC4: 7) | AD4: date of birth | AE4: age | AG4: 8) | AH4: charges
B5: Hawks, Ms. Kelly | C5: Hawks | D5: Ms | E5: Kelly | H5: 0 | K5: Heart Issues | L5: smoker | O5: 47.41 | P5: =IF(O5<18.5,"Underweight",IF(O5<25,"Normal Weight",IF(O5<30,"Overweight","Obesity"))) -> Obesity | S5: 7.47 | T5: =IF(S5<5.7,"normal",IF(S5<6.5,"Prediabetes",IF(S5>6.5,"diabetes"))) -> diabetes | X5: 1992 | Y5: Jul | Z5: 9 | AA5: =CONCATENATE(Z5," ",Y5," ", X5) -> 9 Jul 1992 | AD5: =CONCATENATE(Z5," ",Y5," ",X5) -> 9 Jul 1992 | AE5: =DATEDIF(AD5,TODAY(),"y") -> 34 | AH5: 563.84
B6: Lehner, Mr. Matthew D | C6: Lehner | D6: Mr | E6: Matthew D | H6: 0 | K6: No | L6: yes | O6: 30.36 | P6: =IF(O6<18.5,"Underweight",IF(O6<25,"Normal Weight",IF(O6<30,"Overweight","Obesity"))) -> Obesity | S6: 5.77 | T6: =IF(S6<5.7,"normal",IF(S6<6.5,"Prediabetes",IF(S6>6.5,"diabetes"))) -> Prediabetes | X6: 1992 | Y6: Nov | Z6: 30 | AA6: =CONCATENATE(Z6," ",Y6," ", X6) -> 30 Nov 1992 | AD6: =CONCATENATE(Z6," ",Y6," ",X6) -> 30 Nov 1992 | AE6: =DATEDIF(AD6,TODAY(),"y") -> 33 | AH6: 570.62
B7: Lu, Mr. Phil | C7: Lu | D7: Mr | E7: Phil | H7: 2 | K7: No | L7: yes | O7: 34.485 | P7: =IF(O7<18.5,"Underweight",IF(O7<25,"Normal Weight",IF(O7<30,"Overweight","Obesity"))) -> Obesity | S7: 11.87 | T7: =IF(S7<5.7,"normal",IF(S7<6.5,"Prediabetes",IF(S7>6.5,"diabetes"))) -> diabetes | X7: 1993 | Y7: Jun | Z7: 30 | AA7: =CONCATENATE(Z7," ",Y7," ", X7) -> 30 Jun 1993 | AD7: =CONCATENATE(Z7," ",Y7," ",X7) -> 30 Jun 1993 | AE7: =DATEDIF(AD7,TODAY(),"y") -> 33 | AH7: 600
B8: Osborne, Ms. Kelsey | C8: Osborne | D8: Ms | E8: Kelsey | H8: 0 | K8: No | L8: yes | O8: 38.095 | P8: =IF(O8<18.5,"Underweight",IF(O8<25,"Normal Weight",IF(O8<30,"Overweight","Obesity"))) -> Obesity | S8: 6.05 | T8: =IF(S8<5.7,"normal",IF(S8<6.5,"Prediabetes",IF(S8>6.5,"diabetes"))) -> Prediabetes | X8: 1992 | Y8: Sep | Z8: 13 | AA8: =CONCATENATE(Z8," ",Y8," ", X8) -> 13 Sep 1992 | AD8: =CONCATENATE(Z8," ",Y8," ",X8) -> 13 Sep 1992 | AE8: =DATEDIF(AD8,TODAY(),"y") -> 34 | AH8: 604.54
B9: Kadala, Ms. Kristyn | C9: Kadala | D9: Ms | E9: Kristyn | H9: 0 | K9: No | L9: yes | O9: 35.53 | P9: =IF(O9<18.5,"Underweight",IF(O9<25,"Normal Weight",IF(O9<30,"Overweight","Obesity"))) -> Obesity | S9: 5.45 | T9: =IF(S9<5.7,"normal",IF(S9<6.5,"Prediabetes",IF(S9>6.5,"diabetes"))) -> normal | X9: 1998 | Y9: Jul | Z9: 27 | AA9: =CONCATENATE(Z9," ",Y9," ", X9) -> 27 Jul 1998 | AD9: =CONCATENATE(Z9," ",Y9," ",X9) -> 27 Jul 1998 | AE9: =DATEDIF(AD9,TODAY(),"y") -> 28 | AH9: 637.26
B10: Baker, Mr. Russell B. | C10: Baker | D10: Mr | E10: Russell B | H10: 0 | K10: No | L10: yes | O10: 32.8 | P10: =IF(O10<18.5,"Underweight",IF(O10<25,"Normal Weight",IF(O10<30,"Overweight","Obesity"))) -> Obesity | S10: 6.59 | T10: =IF(S10<5.7,"normal",IF(S10<6.5,"Prediabetes",IF(S10>6.5,"diabetes"))) -> diabetes | X10: 2001 | Y10: Nov | Z10: 20 | AA10: =CONCATENATE(Z10," ",Y10," ", X10) -> 20 Nov 2001 | AD10: =CONCATENATE(Z10," ",Y10," ",X10) -> 20 Nov 2001 | AE10: =DATEDIF(AD10,TODAY(),"y") -> 24 | AH10: 646.14
B11: Macpherson, Mr. Scott | C11: Macpherson | D11: Mr | E11: Scott | H11: 0 | K11: No | L11: yes | O11: 36.4 | P11: =IF(O11<18.5,"Underweight",IF(O11<25,"Normal Weight",IF(O11<30,"Overweight","Obesity"))) -> Obesity | S11: 6.07 | T11: =IF(S11<5.7,"normal",IF(S11<6.5,"Prediabetes",IF(S11>6.5,"diabetes"))) -> Prediabetes | X11: 1993 | Y11: Jun | Z11: 1 | AA11: =CONCATENATE(Z11," ",Y11," ", X11) -> 1 Jun 1993 | AD11: =CONCATENATE(Z11," ",Y11," ",X11) -> 1 Jun 1993 | AE11: =DATEDIF(AD11,TODAY(),"y") -> 33 | AH11: 650
B12: Hallman, Mr. Stephen | C12: Hallman | D12: Mr | E12: Stephen | H12: 3 | K12: No | L12: yes | O12: 36.96 | P12: =IF(O12<18.5,"Underweight",IF(O12<25,"Normal Weight",IF(O12<30,"Overweight","Obesity"))) -> Obesity | S12: 7.93 | T12: =IF(S12<5.7,"normal",IF(S12<6.5,"Prediabetes",IF(S12>6.5,"diabetes"))) -> diabetes | X12: 1995 | Y12: Jul | Z12: 4 | AA12: =CONCATENATE(Z12," ",Y12," ", X12) -> 4 Jul 1995 | AD12: =CONCATENATE(Z12," ",Y12," ",X12) -> 4 Jul 1995 | AE12: =DATEDIF(AD12,TODAY(),"y") -> 31 | AH12: 650
B13: Moran, Mr. Patrick R. | C13: Moran | D13: Mr | E13: Patrick R | H13: 1 | K13: No | L13: yes | O13: 41.14 | P13: =IF(O13<18.5,"Underweight",IF(O13<25,"Normal Weight",IF(O13<30,"Overweight","Obesity"))) -> Obesity | S13: 9.58 | T13: =IF(S13<5.7,"normal",IF(S13<6.5,"Prediabetes",IF(S13>6.5,"diabetes"))) -> diabetes | X13: 2002 | Y13: Nov | Z13: 29 | AA13: =CONCATENATE(Z13," ",Y13," ", X13) -> 29 Nov 2002 | AD13: =CONCATENATE(Z13," ",Y13," ",X13) -> 29 Nov 2002 | AE13: =DATEDIF(AD13,TODAY(),"y") -> 23 | AH13: 668
B14: Benner, Ms. Brooke N. | C14: Benner | D14: Ms | E14: Brooke N | H14: 0 | K14: No | L14: yes | O14: 38.06 | P14: =IF(O14<18.5,"Underweight",IF(O14<25,"Normal Weight",IF(O14<30,"Overweight","Obesity"))) -> Obesity | S14: 10.79 | T14: =IF(S14<5.7,"normal",IF(S14<6.5,"Prediabetes",IF(S14>6.5,"diabetes"))) -> diabetes | X14: 1997 | Y14: Nov | Z14: 9 | AA14: =CONCATENATE(Z14," ",Y14," ", X14) -> 9 Nov 1997 | AD14: =CONCATENATE(Z14," ",Y14," ",X14) -> 9 Nov 1997 | AE14: =DATEDIF(AD14,TODAY(),"y") -> 28 | AH14: 670
B15: Fierro Vargas, Ms. Paola Andrea | C15: Fierro Vargas | D15: Ms | E15: Paola Andrea | H15: 2 | K15: No | L15: yes | O15: 37.7 | P15: =IF(O15<18.5,"Underweight",IF(O15<25,"Normal Weight",IF(O15<30,"Overweight","Obesity"))) -> Obesity | S15: 5.96 | T15: =IF(S15<5.7,"normal",IF(S15<6.5,"Prediabetes",IF(S15>6.5,"diabetes"))) -> Prediabetes | X15: 2001 | Y15: Sep | Z15: 12 | AA15: =CONCATENATE(Z15," ",Y15," ", X15) -> 12 Sep 2001 | AD15: =CONCATENATE(Z15," ",Y15," ",X15) -> 12 Sep 2001 | AE15: =DATEDIF(AD15,TODAY(),"y") -> 25 | AH15: 687.54
B16: Franz, Mr. David | C16: Franz | D16: Mr | E16: David | H16: 0 | K16: No | L16: yes | O16: 42.13 | P16: =IF(O16<18.5,"Underweight",IF(O16<25,"Normal Weight",IF(O16<30,"Overweight","Obesity"))) -> Obesity | S16: 11.9 | T16: =IF(S16<5.7,"normal",IF(S16<6.5,"Prediabetes",IF(S16>6.5,"diabetes"))) -> diabetes | X16: 1999 | Y16: Dec | Z16: 26 | AA16: =CONCATENATE(Z16," ",Y16," ", X16) -> 26 Dec 1999 | AD16: =CONCATENATE(Z16," ",Y16," ",X16) -> 26 Dec 1999 | AE16: =DATEDIF(AD16,TODAY(),"y") -> 26 | AH16: 700
... B75: Turner, Mr. Jeff | C75: Turner | D75: Mr | E75: Jeff | H75: 1 | K75: No | L75: yes | O75: 38.39 | P75: =IF(O75<18.5,"Underweight",IF(O75<25,"Normal Weight",IF(O75<30,"Overweight","Obesity"))) -> Obesity | S75: 4.25 | T75: =IF(S75<5.7,"normal",IF(S75<6.5,"Prediabetes",IF(S75>6.5,"diabetes"))) -> normal | X75: 2002 | Y75: Jul | Z75: 1 | AA75: =CONCATENATE(Z75," ",Y75," ", X75) -> 1 Jul 2002 | AD75: =CONCATENATE(Z75," ",Y75," ",X75) -> 1 Jul 2002 | AE75: =DATEDIF(AD75,TODAY(),"y") -> 24 | AH75: 1241
B76: Rangel, Mr. Elenilton V. Sr. | C76: Rangel | D76: Mr | E76: Elenilton V | F76: Sr | H76: 2 | K76: No | L76: yes | O76: 32.3 | P76: =IF(O76<18.5,"Underweight",IF(O76<25,"Normal Weight",IF(O76<30,"Overweight","Obesity"))) -> Obesity | S76: 4.76 | T76: =IF(S76<5.7,"normal",IF(S76<6.5,"Prediabetes",IF(S76>6.5,"diabetes"))) -> normal | X76: 2003 | Y76: Aug | Z76: 2 | AA76: =CONCATENATE(Z76," ",Y76," ", X76) -> 2 Aug 2003 | AD76: =CONCATENATE(Z76," ",Y76," ",X76) -> 2 Aug 2003 | AE76: =DATEDIF(AD76,TODAY(),"y") -> 23 | AH76: 1241.57
B77: Lacey, Ms. Maurya | C77: Lacey | D77: Ms | E77: Maurya | H77: 2 | K77: No | L77: yes | O77: 48.8 | P77: =IF(O77<18.5,"Underweight",IF(O77<25,"Normal Weight",IF(O77<30,"Overweight","Obesity"))) -> Obesity | S77: 6.22 | T77: =IF(S77<5.7,"normal",IF(S77<6.5,"Prediabetes",IF(S77>6.5,"diabetes"))) -> Prediabetes | X77: 2003 | Y77: Sep | Z77: 15 | AA77: =CONCATENATE(Z77," ",Y77," ", X77) -> 15 Sep 2003 | AD77: =CONCATENATE(Z77," ",Y77," ",X77) -> 15 Sep 2003 | AE77: =DATEDIF(AD77,TODAY(),"y") -> 23 | AH77: 1242.26
B78: Stiger, Ms. Samantha C | C78: Stiger | D78: Ms | E78: Samantha C | H78: 0 | K78: No | L78: yes | O78: 45.5 | P78: =IF(O78<18.5,"Underweight",IF(O78<25,"Normal Weight",IF(O78<30,"Overweight","Obesity"))) -> Obesity | S78: 7.96 | T78: =IF(S78<5.7,"normal",IF(S78<6.5,"Prediabetes",IF(S78>6.5,"diabetes"))) -> diabetes | X78: 2003 | Y78: Sep | Z78: 8 | AA78: =CONCATENATE(Z78," ",Y78," ", X78) -> 8 Sep 2003 | AD78: =CONCATENATE(Z78," ",Y78," ",X78) -> 8 Sep 2003 | AE78: =DATEDIF(AD78,TODAY(),"y") -> 23 | AH78: 1242.82
B79: Caldwell, Ms. Bethany A | C79: Caldwell | D79: Ms | E79: Bethany A | H79: 1 | K79: No | L79: yes | O79: 53.61 | P79: =IF(O79<18.5,"Underweight",IF(O79<25,"Normal Weight",IF(O79<30,"Overweight","Obesity"))) -> Obesity | S79: 10.92 | T79: =IF(S79<5.7,"normal",IF(S79<6.5,"Prediabetes",IF(S79>6.5,"diabetes"))) -> diabetes | X79: 2003 | Y79: Sep | Z79: 15 | AA79: =CONCATENATE(Z79," ",Y79," ", X79) -> 15 Sep 2003 | AD79: =CONCATENATE(Z79," ",Y79," ",X79) -> 15 Sep 2003 | AE79: =DATEDIF(AD79,TODAY(),"y") -> 23 | AH79: 1252.41
B80: Marmillod, Mr. Yves | C80: Marmillod | D80: Mr | E80: Yves | H80: 1 | K80: No | L80: yes | O80: 36.19 | P80: =IF(O80<18.5,"Underweight",IF(O80<25,"Normal Weight",IF(O80<30,"Overweight","Obesity"))) -> Obesity | S80: 11.51 | T80: =IF(S80<5.7,"normal",IF(S80<6.5,"Prediabetes",IF(S80>6.5,"diabetes"))) -> diabetes | X80: 1997 | Y80: Nov | Z80: 4 | AA80: =CONCATENATE(Z80," ",Y80," ", X80) -> 4 Nov 1997 | AD80: =CONCATENATE(Z80," ",Y80," ",X80) -> 4 Nov 1997 | AE80: =DATEDIF(AD80,TODAY(),"y") -> 28 | AH80: 1253
B81: Cloutier-Simons, Ms. Danielle | C81: Cloutier-Simons | D81: Ms | E81: Danielle | H81: 0 | K81: No | L81: yes | O81: 34.6 | P81: =IF(O81<18.5,"Underweight",IF(O81<25,"Normal Weight",IF(O81<30,"Overweight","Obesity"))) -> Obesity | S81: 5.99 | T81: =IF(S81<5.7,"normal",IF(S81<6.5,"Prediabetes",IF(S81>6.5,"diabetes"))) -> Prediabetes | X81: 2003 | Y81: Dec | Z81: 10 | AA81: =CONCATENATE(Z81," ",Y81," ", X81) -> 10 Dec 2003 | AD81: =CONCATENATE(Z81," ",Y81," ",X81) -> 10 Dec 2003 | AE81: =DATEDIF(AD81,TODAY(),"y") -> 22 | AH81: 1253.94
B82: Vegas, Ms. Julia | C82: Vegas | D82: Ms | E82: Julia | H82: 0 | K82: No | L82: yes | O82: 54.12 | P82: =IF(O82<18.5,"Underweight",IF(O82<25,"Normal Weight",IF(O82<30,"Overweight","Obesity"))) -> Obesity | S82: 11.57 | T82: =IF(S82<5.7,"normal",IF(S82<6.5,"Prediabetes",IF(S82>6.5,"diabetes"))) -> diabetes | X82: 2003 | Y82: Oct | Z82: 13 | AA82: =CONCATENATE(Z82," ",Y82," ", X82) -> 13 Oct 2003 | AD82: =CONCATENATE(Z82," ",Y82," ",X82) -> 13 Oct 2003 | AE82: =DATEDIF(AD82,TODAY(),"y") -> 23 | AH82: 1256.3
B83: Cochran, Mr. Joshua | C83: Cochran | D83: Mr | E83: Joshua | H83: 0 | K83: No | L83: yes | O83: 48.82 | P83: =IF(O83<18.5,"Underweight",IF(O83<25,"Normal Weight",IF(O83<30,"Overweight","Obesity"))) -> Obesity | S83: 6.67 | T83: =IF(S83<5.7,"normal",IF(S83<6.5,"Prediabetes",IF(S83>6.5,"diabetes"))) -> diabetes | X83: 2003 | Y83: Oct | Z83: 30 | AA83: =CONCATENATE(Z83," ",Y83," ", X83) -> 30 Oct 2003 | AD83: =CONCATENATE(Z83," ",Y83," ",X83) -> 30 Oct 2003 | AE83: =DATEDIF(AD83,TODAY(),"y") -> 22 | AH83: 1261.44
B84: Holtzapple, Ms. Jennifer | C84: Holtzapple | D84: Ms | E84: Jennifer | H84: 0 | K84: No | L84: yes | O84: 51.01 | P84: =IF(O84<18.5,"Underweight",IF(O84<25,"Normal Weight",IF(O84<30,"Overweight","Obesity"))) -> Obesity | S84: 9.2 | T84: =IF(S84<5.7,"normal",IF(S84<6.5,"Prediabetes",IF(S84>6.5,"diabetes"))) -> diabetes | X84: 2003 | Y84: Aug | Z84: 15 | AA84: =CONCATENATE(Z84," ",Y84," ", X84) -> 15 Aug 2003 | AD84: =CONCATENATE(Z84," ",Y84," ",X84) -> 15 Aug 2003 | AE84: =DATEDIF(AD84,TODAY(),"y") -> 23 | AH84: 1261.86
B85: Meyer, Ms. Gwen M. | C85: Meyer | D85: Ms | E85: Gwen M | H85: 1 | K85: No | L85: yes | O85: 45.65 | P85: =IF(O85<18.5,"Underweight",IF(O85<25,"Normal Weight",IF(O85<30,"Overweight","Obesity"))) -> Obesity | S85: 5.11 | T85: =IF(S85<5.7,"normal",IF(S85<6.5,"Prediabetes",IF(S85>6.5,"diabetes"))) -> normal | X85: 2003 | Y85: Nov | Z85: 21 | AA85: =CONCATENATE(Z85," ",Y85," ", X85) -> 21 Nov 2003 | AD85: =CONCATENATE(Z85," ",Y85," ",X85) -> 21 Nov 2003 | AE85: =DATEDIF(AD85,TODAY(),"y") -> 22 | AH85: 1263.25
B86: Brickley, Mr. Patrick | C86: Brickley | D86: Mr | E86: Patrick | H86: 0 | K86: No | L86: yes | O86: 52.9 | P86: =IF(O86<18.5,"Underweight",IF(O86<25,"Normal Weight",IF(O86<30,"Overweight","Obesity"))) -> Obesity | S86: 5.34 | T86: =IF(S86<5.7,"normal",IF(S86<6.5,"Prediabetes",IF(S86>6.5,"diabetes"))) -> normal | X86: 2002 | Y86: Dec | Z86: 4 | AA86: =CONCATENATE(Z86," ",Y86," ", X86) -> 4 Dec 2002 | AD86: =CONCATENATE(Z86," ",Y86," ",X86) -> 4 Dec 2002 | AE86: =DATEDIF(AD86,TODAY(),"y") -> 23 | AH86: 1267
B87: Magee, Ms. Kate | C87: Magee | D87: Ms | E87: Kate | H87: 1 | K87: No | L87: yes | O87: 45.41 | P87: =IF(O87<18.5,"Underweight",IF(O87<25,"Normal Weight",IF(O87<30,"Overweight","Obesity"))) -> Obesity | S87: 4.03 | T87: =IF(S87<5.7,"normal",IF(S87<6.5,"Prediabetes",IF(S87>6.5,"diabetes"))) -> normal | X87: 1997 | Y87: Oct | Z87: 26 | AA87: =CONCATENATE(Z87," ",Y87," ", X87) -> 26 Oct 1997 | AD87: =CONCATENATE(Z87," ",Y87," ",X87) -> 26 Oct 1997 | AE87: =DATEDIF(AD87,TODAY(),"y") -> 28 | AH87: 1276
B88: Thoma, Mr. Kevin | C88: Thoma | D88: Mr | E88: Kevin | H88: 1 | K88: No | L88: yes | O88: 49.41 | P88: =IF(O88<18.5,"Underweight",IF(O88<25,"Normal Weight",IF(O88<30,"Overweight","Obesity"))) -> Obesity | S88: 4.23 | T88: =IF(S88<5.7,"normal",IF(S88<6.5,"Prediabetes",IF(S88>6.5,"diabetes"))) -> normal | X88: 2004 | Y88: Sep | Z88: 30 | AA88: =CONCATENATE(Z88," ",Y88," ", X88) -> 30 Sep 2004 | AD88: =CONCATENATE(Z88," ",Y88," ",X88) -> 30 Sep 2004 | AE88: =DATEDIF(AD88,TODAY(),"y") -> 22 | AH88: 1283
... B191: Dublin, Mr. Andrew P | C191: Dublin | D191: Mr | E191: Andrew P | H191: 1 | K191: No | L191: No | O191: 53.21 | P191: =IF(O191<18.5,"Underweight",IF(O191<25,"Normal Weight",IF(O191<30,"Overweight","Obesity"))) -> Obesity | S191: 4.27 | T191: =IF(S191<5.7,"normal",IF(S191<6.5,"Prediabetes",IF(S191>6.5,"diabetes"))) -> normal | X191: 1998 | Y191: Oct | Z191: 5 | AA191: =CONCATENATE(Z191," ",Y191," ", X191) -> 5 Oct 1998 | AD191: =CONCATENATE(Z191," ",Y191," ",X191) -> 5 Oct 1998 | AE191: =DATEDIF(AD191,TODAY(),"y") -> 28 | AH191: 1972.95
B192: Cleland, Mr. George M. V | C192: Cleland | D192: Mr | E192: George M | F192: V | H192: 2 | K192: No | L192: yes | O192: 38.73 | P192: =IF(O192<18.5,"Underweight",IF(O192<25,"Normal Weight",IF(O192<30,"Overweight","Obesity"))) -> Obesity | S192: 11.51 | T192: =IF(S192<5.7,"normal",IF(S192<6.5,"Prediabetes",IF(S192>6.5,"diabetes"))) -> diabetes | X192: 1998 | Y192: Sep | Z192: 29 | AA192: =CONCATENATE(Z192," ",Y192," ", X192) -> 29 Sep 1998 | AD192: =CONCATENATE(Z192," ",Y192," ",X192) -> 29 Sep 1998 | AE192: =DATEDIF(AD192,TODAY(),"y") -> 28 | AH192: 1977.82
B193: Evans, Ms. Sarah | C193: Evans | D193: Ms | E193: Sarah | H193: 0 | K193: No | L193: yes | O193: 29.73 | P193: =IF(O193<18.5,"Underweight",IF(O193<25,"Normal Weight",IF(O193<30,"Overweight","Obesity"))) -> Overweight | S193: 7.22 | T193: =IF(S193<5.7,"normal",IF(S193<6.5,"Prediabetes",IF(S193>6.5,"diabetes"))) -> diabetes | X193: 2002 | Y193: Jul | Z193: 16 | AA193: =CONCATENATE(Z193," ",Y193," ", X193) -> 16 Jul 2002 | AD193: =CONCATENATE(Z193," ",Y193," ",X193) -> 16 Jul 2002 | AE193: =DATEDIF(AD193,TODAY(),"y") -> 24 | AH193: 1980.07
B194: Boyd, Ms. Lara | C194: Boyd | D194: Ms | E194: Lara | H194: 1 | K194: No | L194: yes | O194: 34.7 | P194: =IF(O194<18.5,"Underweight",IF(O194<25,"Normal Weight",IF(O194<30,"Overweight","Obesity"))) -> Obesity | S194: 4.37 | T194: =IF(S194<5.7,"normal",IF(S194<6.5,"Prediabetes",IF(S194>6.5,"diabetes"))) -> normal | X194: 1998 | Y194: Dec | Z194: 29 | AA194: =CONCATENATE(Z194," ",Y194," ", X194) -> 29 Dec 1998 | AD194: =CONCATENATE(Z194," ",Y194," ",X194) -> 29 Dec 1998 | AE194: =DATEDIF(AD194,TODAY(),"y") -> 27 | AH194: 1981.58
B195: Roulier, Mr. Sebastien | C195: Roulier | D195: Mr | E195: Sebastien | H195: 1 | K195: No | L195: yes | O195: 38.28 | P195: =IF(O195<18.5,"Underweight",IF(O195<25,"Normal Weight",IF(O195<30,"Overweight","Obesity"))) -> Obesity | S195: 11.56 | T195: =IF(S195<5.7,"normal",IF(S195<6.5,"Prediabetes",IF(S195>6.5,"diabetes"))) -> diabetes | X195: 2002 | Y195: Sep | Z195: 29 | AA195: =CONCATENATE(Z195," ",Y195," ", X195) -> 29 Sep 2002 | AD195: =CONCATENATE(Z195," ",Y195," ",X195) -> 29 Sep 2002 | AE195: =DATEDIF(AD195,TODAY(),"y") -> 24 | AH195: 1984.45
B196: Mullins, Mr. Padraig | C196: Mullins | D196: Mr | E196: Padraig | H196: 0 | K196: No | L196: yes | O196: 33.57 | P196: =IF(O196<18.5,"Underweight",IF(O196<25,"Normal Weight",IF(O196<30,"Overweight","Obesity"))) -> Obesity | S196: 8.82 | T196: =IF(S196<5.7,"normal",IF(S196<6.5,"Prediabetes",IF(S196>6.5,"diabetes"))) -> diabetes | X196: 1998 | Y196: Sep | Z196: 14 | AA196: =CONCATENATE(Z196," ",Y196," ", X196) -> 14 Sep 1998 | AD196: =CONCATENATE(Z196," ",Y196," ",X196) -> 14 Sep 1998 | AE196: =DATEDIF(AD196,TODAY(),"y") -> 28 | AH196: 1986.93
B197: Hofmann, Ms. Heather | C197: Hofmann | D197: Ms | E197: Heather | H197: 1 | K197: No | L197: yes | O197: 52.06 | P197: =IF(O197<18.5,"Underweight",IF(O197<25,"Normal Weight",IF(O197<30,"Overweight","Obesity"))) -> Obesity | S197: 4.69 | T197: =IF(S197<5.7,"normal",IF(S197<6.5,"Prediabetes",IF(S197>6.5,"diabetes"))) -> normal | X197: 2001 | Y197: Aug | Z197: 14 | AA197: =CONCATENATE(Z197," ",Y197," ", X197) -> 14 Aug 2001 | AD197: =CONCATENATE(Z197," ",Y197," ",X197) -> 14 Aug 2001 | AE197: =DATEDIF(AD197,TODAY(),"y") -> 25 | AH197: 2007.95
B198: Garcia Garcia, Mr. Jorge | C198: Garcia Garcia | D198: Mr | E198: Jorge | H198: 1 | K198: No | L198: yes | O198: 38.17 | P198: =IF(O198<18.5,"Underweight",IF(O198<25,"Normal Weight",IF(O198<30,"Overweight","Obesity"))) -> Obesity | S198: 4.53 | T198: =IF(S198<5.7,"normal",IF(S198<6.5,"Prediabetes",IF(S198>6.5,"diabetes"))) -> normal | X198: 2001 | Y198: Jul | Z198: 1 | AA198: =CONCATENATE(Z198," ",Y198," ", X198) -> 1 Jul 2001 | AD198: =CONCATENATE(Z198," ",Y198," ",X198) -> 1 Jul 2001 | AE198: =DATEDIF(AD198,TODAY(),"y") -> 25 | AH198: 2020.18
B199: Klecker, Mr. Jack R | C199: Klecker | D199: Mr | E199: Jack R | H199: 1 | K199: No | L199: yes | O199: 36.955 | P199: =IF(O199<18.5,"Underweight",IF(O199<25,"Normal Weight",IF(O199<30,"Overweight","Obesity"))) -> Obesity | S199: 5.84 | T199: =IF(S199<5.7,"normal",IF(S199<6.5,"Prediabetes",IF(S199>6.5,"diabetes"))) -> Prediabetes | X199: 2001 | Y199: Sep | Z199: 6 | AA199: =CONCATENATE(Z199," ",Y199," ", X199) -> 6 Sep 2001 | AD199: =CONCATENATE(Z199," ",Y199," ",X199) -> 6 Sep 2001 | AE199: =DATEDIF(AD199,TODAY(),"y") -> 25 | AH199: 2020.55
B200: Cancre, Mr. Felix | C200: Cancre | D200: Mr | E200: Felix | H200: 1 | K200: No | L200: yes | O200: 34.4 | P200: =IF(O200<18.5,"Underweight",IF(O200<25,"Normal Weight",IF(O200<30,"Overweight","Obesity"))) -> Obesity | S200: 4.9 | T200: =IF(S200<5.7,"normal",IF(S200<6.5,"Prediabetes",IF(S200>6.5,"diabetes"))) -> normal | X200: 2001 | Y200: Aug | Z200: 4 | AA200: =CONCATENATE(Z200," ",Y200," ", X200) -> 4 Aug 2001 | AD200: =CONCATENATE(Z200," ",Y200," ",X200) -> 4 Aug 2001 | AE200: =DATEDIF(AD200,TODAY(),"y") -> 25 | AH200: 2026.97
B201: Denucci, Mr. Christopher C | C201: Denucci | D201: Mr | E201: Christopher C | H201: 0 | K201: No | L201: yes | O201: 31.73 | P201: =IF(O201<18.5,"Underweight",IF(O201<25,"Normal Weight",IF(O201<30,"Overweight","Obesity"))) -> Obesity | S201: 4.3 | T201: =IF(S201<5.7,"normal",IF(S201<6.5,"Prediabetes",IF(S201>6.5,"diabetes"))) -> normal | X201: 2000 | Y201: Sep | Z201: 2 | AA201: =CONCATENATE(Z201," ",Y201," ", X201) -> 2 Sep 2000 | AD201: =CONCATENATE(Z201," ",Y201," ",X201) -> 2 Sep 2000 | AE201: =DATEDIF(AD201,TODAY(),"y") -> 26 | AH201: 2045.69
B202: Saldana, Mr. Jesse | C202: Saldana | D202: Mr | E202: Jesse | H202: 0 | K202: No | L202: yes | O202: 36.64 | P202: =IF(O202<18.5,"Underweight",IF(O202<25,"Normal Weight",IF(O202<30,"Overweight","Obesity"))) -> Obesity | S202: 11.34 | T202: =IF(S202<5.7,"normal",IF(S202<6.5,"Prediabetes",IF(S202>6.5,"diabetes"))) -> diabetes | X202: 2000 | Y202: Jul | Z202: 26 | AA202: =CONCATENATE(Z202," ",Y202," ", X202) -> 26 Jul 2000 | AD202: =CONCATENATE(Z202," ",Y202," ",X202) -> 26 Jul 2000 | AE202: =DATEDIF(AD202,TODAY(),"y") -> 26 | AH202: 2055.32
...

Sheet Healthcare  
A1: Customer ID | B1: customer name | C1: Daibetes status | D1: BMI | E1: weight status | F1: HBA1C | G1: Heart Issues | H1: Any Transplants | I1: Cancer history | J1: NumberOfMajorSurgeries | K1: smoker | L1: year | M1: month | N1: date | O1: date of birth | P1: age | Q1: children | R1: charges | S1: Hospital tier | T1: City tier | U1: State ID
A2: Id1 | B2: =VLOOKUP(A2,'Customer Names'!A:B,2,0) -> Hawks, Ms. Kelly | C2: =IF(F2<5.7,"Normal",IF(F2<6.5,"Prediabetes","Diabetes")) -> Diabetes | D2: =VLOOKUP(A2,'Medical Examinations'!A:H,2,0) -> 47.41 | E2: =IF(D2<18.5,"Underweight",IF(D2<25,"Normal Weight",IF(D2<30,"Overweight","Obesity"))) -> Obesity | F2: =VLOOKUP(A2,'Medical Examinations'!A:H,3,0) -> 7.47 | G2: =VLOOKUP(A2,'Medical Examinations'!A:H,4,0) -> No | H2: =VLOOKUP(A2,'Medical Examinations'!A:H,5,0) -> No | I2: =VLOOKUP(A2,'Medical Examinations'!A:H,6,0) -> No | J2: =VLOOKUP(A2,'Medical Examinations'!A:H,7,0) -> No major surgery | K2: =VLOOKUP(A2,'Medical Examinations'!A:H,8,0) -> yes | L2: =VLOOKUP(A2,'Hospitalisation Details'!A:I,2,0) -> 1968 | M2: =VLOOKUP(A2,'Hospitalisation Details'!A:I,3,0) -> Oct | N2: =VLOOKUP(A2,'Hospitalisation Details'!A:I,4,0) -> 12 | O2: =CONCATENATE(N2," ",M2," ",L2) -> 12 Oct 1968 | P2: =DATEDIF(O2,TODAY(),"y") -> 58 | Q2: =VLOOKUP(A2,'Hospitalisation Details'!A:I,5,0) -> 0 | R2: =VLOOKUP(A2,'Hospitalisation Details'!A:I,6,0) -> 63770.43 | S2: =VLOOKUP(A2,'Hospitalisation Details'!A:I,7,0) -> tier - 1 | T2: =VLOOKUP(A2,'Hospitalisation Details'!A:I,8,0) -> tier - 3 | U2: =VLOOKUP(A2,'Hospitalisation Details'!A:I,9,0) -> R1013
A3: Id2 | B3: =VLOOKUP(A3,'Customer Names'!A:B,2,0) -> Lehner, Mr. Matthew D | C3: =IF(F3<5.7,"Normal",IF(F3<6.5,"Prediabetes","Diabetes")) -> Prediabetes | D3: =VLOOKUP(A3,'Medical Examinations'!A:H,2,0) -> 30.36 | E3: =IF(D3<18.5,"Underweight",IF(D3<25,"Normal Weight",IF(D3<30,"Overweight","Obesity"))) -> Obesity | F3: =VLOOKUP(A3,'Medical Examinations'!A:H,3,0) -> 5.77 | G3: =VLOOKUP(A3,'Medical Examinations'!A:H,4,0) -> No | H3: =VLOOKUP(A3,'Medical Examinations'!A:H,5,0) -> No | I3: =VLOOKUP(A3,'Medical Examinations'!A:H,6,0) -> No | J3: =VLOOKUP(A3,'Medical Examinations'!A:H,7,0) -> No major surgery | K3: =VLOOKUP(A3,'Medical Examinations'!A:H,8,0) -> yes | L3: =VLOOKUP(A3,'Hospitalisation Details'!A:I,2,0) -> 1977 | M3: =VLOOKUP(A3,'Hospitalisation Details'!A:I,3,0) -> Jun | N3: =VLOOKUP(A3,'Hospitalisation Details'!A:I,4,0) -> 8 | O3: =CONCATENATE(N3," ",M3," ",L3) -> 8 Jun 1977 | P3: =DATEDIF(O3,TODAY(),"y") -> 49 | Q3: =VLOOKUP(A3,'Hospitalisation Details'!A:I,5,0) -> 0 | R3: =VLOOKUP(A3,'Hospitalisation Details'!A:I,6,0) -> 62592.87 | S3: =VLOOKUP(A3,'Hospitalisation Details'!A:I,7,0) -> tier - 2 | T3: =VLOOKUP(A3,'Hospitalisation Details'!A:I,8,0) -> tier - 3 | U3: =VLOOKUP(A3,'Hospitalisation Details'!A:I,9,0) -> R1013
A4: Id3 | B4: =VLOOKUP(A4,'Customer Names'!A:B,2,0) -> Lu, Mr. Phil | C4: =IF(F4<5.7,"Normal",IF(F4<6.5,"Prediabetes","Diabetes")) -> Diabetes | D4: =VLOOKUP(A4,'Medical Examinations'!A:H,2,0) -> 34.485 | E4: =IF(D4<18.5,"Underweight",IF(D4<25,"Normal Weight",IF(D4<30,"Overweight","Obesity"))) -> Obesity | F4: =VLOOKUP(A4,'Medical Examinations'!A:H,3,0) -> 11.87 | G4: =VLOOKUP(A4,'Medical Examinations'!A:H,4,0) -> yes | H4: =VLOOKUP(A4,'Medical Examinations'!A:H,5,0) -> No | I4: =VLOOKUP(A4,'Medical Examinations'!A:H,6,0) -> No | J4: =VLOOKUP(A4,'Medical Examinations'!A:H,7,0) -> 2 | K4: =VLOOKUP(A4,'Medical Examinations'!A:H,8,0) -> yes | L4: =VLOOKUP(A4,'Hospitalisation Details'!A:I,2,0) -> 1970 | M4: =VLOOKUP(A4,'Hospitalisation Details'!A:I,3,0) -> SEP | N4: =VLOOKUP(A4,'Hospitalisation Details'!A:I,4,0) -> 11 | O4: =CONCATENATE(N4," ",M4," ",L4) -> 11 SEP 1970 | P4: =DATEDIF(O4,TODAY(),"y") -> 56 | Q4: =VLOOKUP(A4,'Hospitalisation Details'!A:I,5,0) -> 3 | R4: =VLOOKUP(A4,'Hospitalisation Details'!A:I,6,0) -> 60021.4 | S4: =VLOOKUP(A4,'Hospitalisation Details'!A:I,7,0) -> tier - 1 | T4: =VLOOKUP(A4,'Hospitalisation Details'!A:I,8,0) -> tier - 1 | U4: =VLOOKUP(A4,'Hospitalisation Details'!A:I,9,0) -> R1012
A5: Id4 | B5: =VLOOKUP(A5,'Customer Names'!A:B,2,0) -> Osborne, Ms. Kelsey | C5: =IF(F5<5.7,"Normal",IF(F5<6.5,"Prediabetes","Diabetes")) -> Prediabetes | D5: =VLOOKUP(A5,'Medical Examinations'!A:H,2,0) -> 38.095 | E5: =IF(D5<18.5,"Underweight",IF(D5<25,"Normal Weight",IF(D5<30,"Overweight","Obesity"))) -> Obesity | F5: =VLOOKUP(A5,'Medical Examinations'!A:H,3,0) -> 6.05 | G5: =VLOOKUP(A5,'Medical Examinations'!A:H,4,0) -> No | H5: =VLOOKUP(A5,'Medical Examinations'!A:H,5,0) -> No | I5: =VLOOKUP(A5,'Medical Examinations'!A:H,6,0) -> No | J5: =VLOOKUP(A5,'Medical Examinations'!A:H,7,0) -> No major surgery | K5: =VLOOKUP(A5,'Medical Examinations'!A:H,8,0) -> yes | L5: =VLOOKUP(A5,'Hospitalisation Details'!A:I,2,0) -> 1991 | M5: =VLOOKUP(A5,'Hospitalisation Details'!A:I,3,0) -> Jun | N5: =VLOOKUP(A5,'Hospitalisation Details'!A:I,4,0) -> 6 | O5: =CONCATENATE(N5," ",M5," ",L5) -> 6 Jun 1991 | P5: =DATEDIF(O5,TODAY(),"y") -> 35 | Q5: =VLOOKUP(A5,'Hospitalisation Details'!A:I,5,0) -> 1 | R5: =VLOOKUP(A5,'Hospitalisation Details'!A:I,6,0) -> 58571.07 | S5: =VLOOKUP(A5,'Hospitalisation Details'!A:I,7,0) -> tier - 1 | T5: =VLOOKUP(A5,'Hospitalisation Details'!A:I,8,0) -> tier - 3 | U5: =VLOOKUP(A5,'Hospitalisation Details'!A:I,9,0) -> R1024
A6: Id5 | B6: =VLOOKUP(A6,'Customer Names'!A:B,2,0) -> Kadala, Ms. Kristyn | C6: =IF(F6<5.7,"Normal",IF(F6<6.5,"Prediabetes","Diabetes")) -> Normal | D6: =VLOOKUP(A6,'Medical Examinations'!A:H,2,0) -> 35.53 | E6: =IF(D6<18.5,"Underweight",IF(D6<25,"Normal Weight",IF(D6<30,"Overweight","Obesity"))) -> Obesity | F6: =VLOOKUP(A6,'Medical Examinations'!A:H,3,0) -> 5.45 | G6: =VLOOKUP(A6,'Medical Examinations'!A:H,4,0) -> No | H6: =VLOOKUP(A6,'Medical Examinations'!A:H,5,0) -> No | I6: =VLOOKUP(A6,'Medical Examinations'!A:H,6,0) -> No | J6: =VLOOKUP(A6,'Medical Examinations'!A:H,7,0) -> No major surgery | K6: =VLOOKUP(A6,'Medical Examinations'!A:H,8,0) -> yes | L6: =VLOOKUP(A6,'Hospitalisation Details'!A:I,2,0) -> 1989 | M6: =VLOOKUP(A6,'Hospitalisation Details'!A:I,3,0) -> Jun | N6: =VLOOKUP(A6,'Hospitalisation Details'!A:I,4,0) -> 19 | O6: =CONCATENATE(N6," ",M6," ",L6) -> 19 Jun 1989 | P6: =DATEDIF(O6,TODAY(),"y") -> 37 | Q6: =VLOOKUP(A6,'Hospitalisation Details'!A:I,5,0) -> 0 | R6: =VLOOKUP(A6,'Hospitalisation Details'!A:I,6,0) -> 55135.4 | S6: =VLOOKUP(A6,'Hospitalisation Details'!A:I,7,0) -> tier - 1 | T6: =VLOOKUP(A6,'Hospitalisation Details'!A:I,8,0) -> tier - 2 | U6: =VLOOKUP(A6,'Hospitalisation Details'!A:I,9,0) -> R1012
A7: Id6 | B7: =VLOOKUP(A7,'Customer Names'!A:B,2,0) -> Baker, Mr. Russell B. | C7: =IF(F7<5.7,"Normal",IF(F7<6.5,"Prediabetes","Diabetes")) -> Diabetes | D7: =VLOOKUP(A7,'Medical Examinations'!A:H,2,0) -> 32.8 | E7: =IF(D7<18.5,"Underweight",IF(D7<25,"Normal Weight",IF(D7<30,"Overweight","Obesity"))) -> Obesity | F7: =VLOOKUP(A7,'Medical Examinations'!A:H,3,0) -> 6.59 | G7: =VLOOKUP(A7,'Medical Examinations'!A:H,4,0) -> No | H7: =VLOOKUP(A7,'Medical Examinations'!A:H,5,0) -> No | I7: =VLOOKUP(A7,'Medical Examinations'!A:H,6,0) -> No | J7: =VLOOKUP(A7,'Medical Examinations'!A:H,7,0) -> No major surgery | K7: =VLOOKUP(A7,'Medical Examinations'!A:H,8,0) -> yes | L7: =VLOOKUP(A7,'Hospitalisation Details'!A:I,2,0) -> 1962 | M7: =VLOOKUP(A7,'Hospitalisation Details'!A:I,3,0) -> Aug | N7: =VLOOKUP(A7,'Hospitalisation Details'!A:I,4,0) -> 4 | O7: =CONCATENATE(N7," ",M7," ",L7) -> 4 Aug 1962 | P7: =DATEDIF(O7,TODAY(),"y") -> 64 | Q7: =VLOOKUP(A7,'Hospitalisation Details'!A:I,5,0) -> 0 | R7: =VLOOKUP(A7,'Hospitalisation Details'!A:I,6,0) -> 52590.83 | S7: =VLOOKUP(A7,'Hospitalisation Details'!A:I,7,0) -> tier - 1 | T7: =VLOOKUP(A7,'Hospitalisation Details'!A:I,8,0) -> tier - 3 | U7: =VLOOKUP(A7,'Hospitalisation Details'!A:I,9,0) -> R1011
A8: Id7 | B8: =VLOOKUP(A8,'Customer Names'!A:B,2,0) -> Macpherson, Mr. Scott | C8: =IF(F8<5.7,"Normal",IF(F8<6.5,"Prediabetes","Diabetes")) -> Prediabetes | D8: =VLOOKUP(A8,'Medical Examinations'!A:H,2,0) -> 36.4 | E8: =IF(D8<18.5,"Underweight",IF(D8<25,"Normal Weight",IF(D8<30,"Overweight","Obesity"))) -> Obesity | F8: =VLOOKUP(A8,'Medical Examinations'!A:H,3,0) -> 6.07 | G8: =VLOOKUP(A8,'Medical Examinations'!A:H,4,0) -> No | H8: =VLOOKUP(A8,'Medical Examinations'!A:H,5,0) -> No | I8: =VLOOKUP(A8,'Medical Examinations'!A:H,6,0) -> No | J8: =VLOOKUP(A8,'Medical Examinations'!A:H,7,0) -> No major surgery | K8: =VLOOKUP(A8,'Medical Examinations'!A:H,8,0) -> yes | L8: =VLOOKUP(A8,'Hospitalisation Details'!A:I,2,0) -> 1994 | M8: =VLOOKUP(A8,'Hospitalisation Details'!A:I,3,0) -> Oct | N8: =VLOOKUP(A8,'Hospitalisation Details'!A:I,4,0) -> 27 | O8: =CONCATENATE(N8," ",M8," ",L8) -> 27 Oct 1994 | P8: =DATEDIF(O8,TODAY(),"y") -> 31 | Q8: =VLOOKUP(A8,'Hospitalisation Details'!A:I,5,0) -> 1 | R8: =VLOOKUP(A8,'Hospitalisation Details'!A:I,6,0) -> 51194.56 | S8: =VLOOKUP(A8,'Hospitalisation Details'!A:I,7,0) -> tier - 1 | T8: =VLOOKUP(A8,'Hospitalisation Details'!A:I,8,0) -> tier - 3 | U8: =VLOOKUP(A8,'Hospitalisation Details'!A:I,9,0) -> R1011
A9: Id8 | B9: =VLOOKUP(A9,'Customer Names'!A:B,2,0) -> Hallman, Mr. Stephen | C9: =IF(F9<5.7,"Normal",IF(F9<6.5,"Prediabetes","Diabetes")) -> Diabetes | D9: =VLOOKUP(A9,'Medical Examinations'!A:H,2,0) -> 36.96 | E9: =IF(D9<18.5,"Underweight",IF(D9<25,"Normal Weight",IF(D9<30,"Overweight","Obesity"))) -> Obesity | F9: =VLOOKUP(A9,'Medical Examinations'!A:H,3,0) -> 7.93 | G9: =VLOOKUP(A9,'Medical Examinations'!A:H,4,0) -> No | H9: =VLOOKUP(A9,'Medical Examinations'!A:H,5,0) -> No | I9: =VLOOKUP(A9,'Medical Examinations'!A:H,6,0) -> No | J9: =VLOOKUP(A9,'Medical Examinations'!A:H,7,0) -> 3 | K9: =VLOOKUP(A9,'Medical Examinations'!A:H,8,0) -> yes | L9: =VLOOKUP(A9,'Hospitalisation Details'!A:I,2,0) -> 1958 | M9: =VLOOKUP(A9,'Hospitalisation Details'!A:I,3,0) -> Jun | N9: =VLOOKUP(A9,'Hospitalisation Details'!A:I,4,0) -> 27 | O9: =CONCATENATE(N9," ",M9," ",L9) -> 27 Jun 1958 | P9: =DATEDIF(O9,TODAY(),"y") -> 68 | Q9: =VLOOKUP(A9,'Hospitalisation Details'!A:I,5,0) -> 2 | R9: =VLOOKUP(A9,'Hospitalisation Details'!A:I,6,0) -> 49577.66 | S9: =VLOOKUP(A9,'Hospitalisation Details'!A:I,7,0) -> tier - 2 | T9: =VLOOKUP(A9,'Hospitalisation Details'!A:I,8,0) -> tier - 2 | U9: =VLOOKUP(A9,'Hospitalisation Details'!A:I,9,0) -> R1013
A10: Id9 | B10: =VLOOKUP(A10,'Customer Names'!A:B,2,0) -> Moran, Mr. Patrick R. | C10: =IF(F10<5.7,"Normal",IF(F10<6.5,"Prediabetes","Diabetes")) -> Diabetes | D10: =VLOOKUP(A10,'Medical Examinations'!A:H,2,0) -> 41.14 | E10: =IF(D10<18.5,"Underweight",IF(D10<25,"Normal Weight",IF(D10<30,"Overweight","Obesity"))) -> Obesity | F10: =VLOOKUP(A10,'Medical Examinations'!A:H,3,0) -> 9.58 | G10: =VLOOKUP(A10,'Medical Examinations'!A:H,4,0) -> yes | H10: =VLOOKUP(A10,'Medical Examinations'!A:H,5,0) -> No | I10: =VLOOKUP(A10,'Medical Examinations'!A:H,6,0) -> Yes | J10: =VLOOKUP(A10,'Medical Examinations'!A:H,7,0) -> 1 | K10: =VLOOKUP(A10,'Medical Examinations'!A:H,8,0) -> yes | L10: =VLOOKUP(A10,'Hospitalisation Details'!A:I,2,0) -> 1963 | M10: =VLOOKUP(A10,'Hospitalisation Details'!A:I,3,0) -> Sep | N10: =VLOOKUP(A10,'Hospitalisation Details'!A:I,4,0) -> 4 | O10: =CONCATENATE(N10," ",M10," ",L10) -> 4 Sep 1963 | P10: =DATEDIF(O10,TODAY(),"y") -> 63 | Q10: =VLOOKUP(A10,'Hospitalisation Details'!A:I,5,0) -> 1 | R10: =VLOOKUP(A10,'Hospitalisation Details'!A:I,6,0) -> 48970.25 | S10: =VLOOKUP(A10,'Hospitalisation Details'!A:I,7,0) -> tier - 1 | T10: =VLOOKUP(A10,'Hospitalisation Details'!A:I,8,0) -> tier - 2 | U10: =VLOOKUP(A10,'Hospitalisation Details'!A:I,9,0) -> R1013
A11: Id10 | B11: =VLOOKUP(A11,'Customer Names'!A:B,2,0) -> Benner, Ms. Brooke N. | C11: =IF(F11<5.7,"Normal",IF(F11<6.5,"Prediabetes","Diabetes")) -> Diabetes | D11: =VLOOKUP(A11,'Medical Examinations'!A:H,2,0) -> 38.06 | E11: =IF(D11<18.5,"Underweight",IF(D11<25,"Normal Weight",IF(D11<30,"Overweight","Obesity"))) -> Obesity | F11: =VLOOKUP(A11,'Medical Examinations'!A:H,3,0) -> 10.79 | G11: =VLOOKUP(A11,'Medical Examinations'!A:H,4,0) -> No | H11: =VLOOKUP(A11,'Medical Examinations'!A:H,5,0) -> No | I11: =VLOOKUP(A11,'Medical Examinations'!A:H,6,0) -> No | J11: =VLOOKUP(A11,'Medical Examinations'!A:H,7,0) -> No major surgery | K11: =VLOOKUP(A11,'Medical Examinations'!A:H,8,0) -> yes | L11: =VLOOKUP(A11,'Hospitalisation Details'!A:I,2,0) -> 1978 | M11: =VLOOKUP(A11,'Hospitalisation Details'!A:I,3,0) -> Dec | N11: =VLOOKUP(A11,'Hospitalisation Details'!A:I,4,0) -> 29 | O11: =CONCATENATE(N11," ",M11," ",L11) -> 29 Dec 1978 | P11: =DATEDIF(O11,TODAY(),"y") -> 47 | Q11: =VLOOKUP(A11,'Hospitalisation Details'!A:I,5,0) -> 0 | R11: =VLOOKUP(A11,'Hospitalisation Details'!A:I,6,0) -> 48885.14 | S11: =VLOOKUP(A11,'Hospitalisation Details'!A:I,7,0) -> tier - 1 | T11: =VLOOKUP(A11,'Hospitalisation Details'!A:I,8,0) -> tier - 2 | U11: =VLOOKUP(A11,'Hospitalisation Details'!A:I,9,0) -> R1013
A12: Id11 | B12: =VLOOKUP(A12,'Customer Names'!A:B,2,0) -> Fierro Vargas, Ms. Paola Andrea | C12: =IF(F12<5.7,"Normal",IF(F12<6.5,"Prediabetes","Diabetes")) -> Prediabetes | D12: =VLOOKUP(A12,'Medical Examinations'!A:H,2,0) -> 37.7 | E12: =IF(D12<18.5,"Underweight",IF(D12<25,"Normal Weight",IF(D12<30,"Overweight","Obesity"))) -> Obesity | F12: =VLOOKUP(A12,'Medical Examinations'!A:H,3,0) -> 5.96 | G12: =VLOOKUP(A12,'Medical Examinations'!A:H,4,0) -> yes | H12: =VLOOKUP(A12,'Medical Examinations'!A:H,5,0) -> No | I12: =VLOOKUP(A12,'Medical Examinations'!A:H,6,0) -> No | J12: =VLOOKUP(A12,'Medical Examinations'!A:H,7,0) -> 2 | K12: =VLOOKUP(A12,'Medical Examinations'!A:H,8,0) -> yes | L12: =VLOOKUP(A12,'Hospitalisation Details'!A:I,2,0) -> 1959 | M12: =VLOOKUP(A12,'Hospitalisation Details'!A:I,3,0) -> Jul | N12: =VLOOKUP(A12,'Hospitalisation Details'!A:I,4,0) -> 22 | O12: =CONCATENATE(N12," ",M12," ",L12) -> 22 Jul 1959 | P12: =DATEDIF(O12,TODAY(),"y") -> 67 | Q12: =VLOOKUP(A12,'Hospitalisation Details'!A:I,5,0) -> 0 | R12: =VLOOKUP(A12,'Hospitalisation Details'!A:I,6,0) -> 48824.45 | S12: =VLOOKUP(A12,'Hospitalisation Details'!A:I,7,0) -> tier - 2 | T12: =VLOOKUP(A12,'Hospitalisation Details'!A:I,8,0) -> tier - 1 | U12: =VLOOKUP(A12,'Hospitalisation Details'!A:I,9,0) -> R1011
A13: Id12 | B13: =VLOOKUP(A13,'Customer Names'!A:B,2,0) -> Franz, Mr. David | C13: =IF(F13<5.7,"Normal",IF(F13<6.5,"Prediabetes","Diabetes")) -> Diabetes | D13: =VLOOKUP(A13,'Medical Examinations'!A:H,2,0) -> 42.13 | E13: =IF(D13<18.5,"Underweight",IF(D13<25,"Normal Weight",IF(D13<30,"Overweight","Obesity"))) -> Obesity | F13: =VLOOKUP(A13,'Medical Examinations'!A:H,3,0) -> 11.9 | G13: =VLOOKUP(A13,'Medical Examinations'!A:H,4,0) -> No | H13: =VLOOKUP(A13,'Medical Examinations'!A:H,5,0) -> No | I13: =VLOOKUP(A13,'Medical Examinations'!A:H,6,0) -> No | J13: =VLOOKUP(A13,'Medical Examinations'!A:H,7,0) -> No major surgery | K13: =VLOOKUP(A13,'Medical Examinations'!A:H,8,0) -> yes | L13: =VLOOKUP(A13,'Hospitalisation Details'!A:I,2,0) -> 1965 | M13: =VLOOKUP(A13,'Hospitalisation Details'!A:I,3,0) -> Oct | N13: =VLOOKUP(A13,'Hospitalisation Details'!A:I,4,0) -> 27 | O13: =CONCATENATE(N13," ",M13," ",L13) -> 27 Oct 1965 | P13: =DATEDIF(O13,TODAY(),"y") -> 60 | Q13: =VLOOKUP(A13,'Hospitalisation Details'!A:I,5,0) -> 1 | R13: =VLOOKUP(A13,'Hospitalisation Details'!A:I,6,0) -> 48675.52 | S13: =VLOOKUP(A13,'Hospitalisation Details'!A:I,7,0) -> tier - 1 | T13: =VLOOKUP(A13,'Hospitalisation Details'!A:I,8,0) -> tier - 2 | U13: =VLOOKUP(A13,'Hospitalisation Details'!A:I,9,0) -> R1013
... A2336: Id2335 | B2336: =VLOOKUP(A2336,'Customer Names'!A:B,2,0) -> German, Mr. Aaron K | C2336: =IF(F2336<5.7,"Normal",IF(F2336<6.5,"Prediabetes","Diabetes")) -> Normal | D2336: =VLOOKUP(A2336,'Medical Examinations'!A:H,2,0) -> 17.58 | E2336: =IF(D2336<18.5,"Underweight",IF(D2336<25,"Normal Weight",IF(D2336<30,"Overweight","Obesity"))) -> Underweight | F2336: =VLOOKUP(A2336,'Medical Examinations'!A:H,3,0) -> 4.51 | G2336: =VLOOKUP(A2336,'Medical Examinations'!A:H,4,0) -> No | H2336: =VLOOKUP(A2336,'Medical Examinations'!A:H,5,0) -> No | I2336: =VLOOKUP(A2336,'Medical Examinations'!A:H,6,0) -> No | J2336: =VLOOKUP(A2336,'Medical Examinations'!A:H,7,0) -> 1 | K2336: =VLOOKUP(A2336,'Medical Examinations'!A:H,8,0) -> No | L2336: =VLOOKUP(A2336,'Hospitalisation Details'!A:I,2,0) -> 1992 | M2336: =VLOOKUP(A2336,'Hospitalisation Details'!A:I,3,0) -> Jul | N2336: =VLOOKUP(A2336,'Hospitalisation Details'!A:I,4,0) -> 9 | O2336: =CONCATENATE(N2336," ",M2336," ",L2336) -> 9 Jul 1992 | P2336: =DATEDIF(O2336,TODAY(),"y") -> 34 | Q2336: =VLOOKUP(A2336,'Hospitalisation Details'!A:I,5,0) -> 0 | R2336: =VLOOKUP(A2336,'Hospitalisation Details'!A:I,6,0) -> 563.84 | S2336: =VLOOKUP(A2336,'Hospitalisation Details'!A:I,7,0) -> tier - 2 | T2336: =VLOOKUP(A2336,'Hospitalisation Details'!A:I,8,0) -> tier - 3 | U2336: =VLOOKUP(A2336,'Hospitalisation Details'!A:I,9,0) -> R1013

Sheet pivot charts 
A1: () Analysis using Pie/Donut Chart:
A3: Row Labels | B3: Count of Cancer history
A4: No | B4: 1847
A5: yes | B5: 488
A6: Grand Total | B6: 2335
A16: Row Labels | B16: Average of HBA1C | C16: Sum of NumberOfMajorSurgeries
A17: No | B17: 6.7246661 | C17: 745
A18: yes | B18: 5.1844578 | C18: 95
A19: Grand Total | B19: 6.6199672 | C19: 840
A29: ()Analysis using Column/Bar Chart:
A32: Average of HBA1C | B32: Column Labels
A33: Row Labels | B33: Diabetes | C33: Normal | D33: Prediabetes | E33: Grand Total
A34: Obesity | B34: 9.308487 | C34: 4.8370053 | D34: 6.0418987 | E34: 6.6199672
A35: Grand Total | B35: 9.308487 | C35: 4.8370053 | D35: 6.0418987 | E35: 6.6199672
A44: ()Analysis using Line/Scatter Plot:
A46: Row Labels | B46: Sum of BMI | C46: Sum of HBA1C
A47: 21 | B47: 1078.34 | C47: 151.06
A48: 22 | B48: 1897.865 | C48: 282.21
A49: 23 | B49: 1036.36 | C49: 206
A50: 24 | B50: 796.84 | C50: 166.22
A51: 25 | B51: 1156.34 | C51: 161.36
A52: 26 | B52: 1056.345 | C52: 147.52
A53: 27 | B53: 543.275 | C53: 74.46
A54: 28 | B54: 952.08 | C54: 131.86
A55: 29 | B55: 874.425 | C55: 117.01
A56: 30 | B56: 1183.52 | C56: 160.31
A57: 31 | B57: 859.955 | C57: 122.28
A58: 32 | B58: 1257.905 | C58: 170.43
... A94: 68 | B94: 218.165 | C94: 53.9
A95: Grand Total | B95: 45904.15 | C95: 8082.98

Sheet dash board 
D9: Row Labels | E9: Count of Cancer history | G9: Row Labels | H9: Average of HBA1C | I9: Sum of NumberOfMajorSurgeries | K9: Average of HBA1C | L9: Column Labels
D10: No | E10: 939 | G10: No | H10: 6.7246661 | I10: 745 | K10: Row Labels | L10: Diabetes | M10: Normal | N10: Prediabetes | O10: Grand Total
D11: yes | E11: 282 | G11: yes | H11: 5.1844578 | I11: 95 | K11: Obesity | L11: 9.308487 | M11: 4.8370053 | N11: 6.0418987 | O11: 6.6199672
D12: Grand Total | E12: 1221 | G12: Grand Total | H12: 6.6199672 | I12: 840 | K12: Grand Total | L12: 9.308487 | M12: 4.8370053 | N12: 6.0418987 | O12: 6.6199672
